[2023-07-07 23:13:39] [DEBUG   ] discord.client: on_ready has successfully been registered as an event
[2023-07-07 23:13:39] [DEBUG   ] discord.client: on_guild_join has successfully been registered as an event
[2023-07-07 23:13:39] [DEBUG   ] discord.client: on_member_join has successfully been registered as an event
[2023-07-07 23:13:39] [INFO    ] discord.client: logging in using static token
[2023-07-07 23:13:41] [INFO    ] discord.gateway: Shard ID None has connected to Gateway (Session ID: 947256d1b978d364fe9355cea03f8e17).
[2023-07-07 23:13:43] [INFO    ] discord: Logged in as ajoke#0521 (ID: 1123604895300329502).
[2023-07-07 23:22:53] [DEBUG   ] discord.client: on_ready has successfully been registered as an event
[2023-07-07 23:22:53] [DEBUG   ] discord.client: on_guild_join has successfully been registered as an event
[2023-07-07 23:22:53] [DEBUG   ] discord.client: on_member_join has successfully been registered as an event
[2023-07-07 23:22:53] [INFO    ] discord.client: logging in using static token
[2023-07-07 23:22:54] [INFO    ] discord.gateway: Shard ID None has connected to Gateway (Session ID: e01dc384ffb7730d3b03410536a6e071).
[2023-07-07 23:22:56] [INFO    ] discord: Logged in as ajoke#0521 (ID: 1123604895300329502).
[2023-07-07 23:24:13] [ERROR   ] discord.client: Ignoring exception in on_guild_join
Traceback (most recent call last):
  File "C:\Users\Victor Momodu\Documents\Programming\Software Engineering\Code\DiscordManager\.venv\lib\site-packages\discord\client.py", line 441, in _run_event
    await coro(*args, **kwargs)
  File "c:\Users\Victor Momodu\Documents\Programming\Software Engineering\Code\DiscordManager\event_listener.py", line 46, in on_guild_join
    logger.info(f"{guild.name}-{guild-id} has just been added.")
TypeError: unsupported operand type(s) for -: 'Guild' and 'builtin_function_or_method'
[2023-07-07 23:27:11] [DEBUG   ] discord.client: on_ready has successfully been registered as an event
[2023-07-07 23:27:11] [DEBUG   ] discord.client: on_guild_join has successfully been registered as an event
[2023-07-07 23:27:11] [DEBUG   ] discord.client: on_member_join has successfully been registered as an event
[2023-07-07 23:27:11] [INFO    ] discord.client: logging in using static token
[2023-07-07 23:27:13] [INFO    ] discord.gateway: Shard ID None has connected to Gateway (Session ID: 6fe7d7697a71c39d4261042761643c2d).
[2023-07-07 23:27:15] [INFO    ] discord: Logged in as ajoke#0521 (ID: 1123604895300329502).
[2023-07-07 23:27:27] [ERROR   ] discord.ext.commands.bot: Ignoring exception in command leave
Traceback (most recent call last):
  File "C:\Users\Victor Momodu\Documents\Programming\Software Engineering\Code\DiscordManager\.venv\lib\site-packages\discord\ext\commands\core.py", line 235, in wrapped
    ret = await coro(*args, **kwargs)
  File "c:\Users\Victor Momodu\Documents\Programming\Software Engineering\Code\DiscordManager\event_listener.py", line 58, in leave
    await ctx.send("Leaving server...")
  File "C:\Users\Victor Momodu\Documents\Programming\Software Engineering\Code\DiscordManager\.venv\lib\site-packages\discord\ext\commands\context.py", line 1024, in send
    return await super().send(
  File "C:\Users\Victor Momodu\Documents\Programming\Software Engineering\Code\DiscordManager\.venv\lib\site-packages\discord\abc.py", line 1562, in send
    data = await state.http.send_message(channel.id, params=params)
  File "C:\Users\Victor Momodu\Documents\Programming\Software Engineering\Code\DiscordManager\.venv\lib\site-packages\discord\http.py", line 739, in request
    raise Forbidden(response, data)
discord.errors.Forbidden: 403 Forbidden (error code: 50001): Missing Access

The above exception was the direct cause of the following exception:

Traceback (most recent call last):
  File "C:\Users\Victor Momodu\Documents\Programming\Software Engineering\Code\DiscordManager\.venv\lib\site-packages\discord\ext\commands\bot.py", line 1350, in invoke
    await ctx.command.invoke(ctx)
  File "C:\Users\Victor Momodu\Documents\Programming\Software Engineering\Code\DiscordManager\.venv\lib\site-packages\discord\ext\commands\core.py", line 1029, in invoke
    await injected(*ctx.args, **ctx.kwargs)  # type: ignore
  File "C:\Users\Victor Momodu\Documents\Programming\Software Engineering\Code\DiscordManager\.venv\lib\site-packages\discord\ext\commands\core.py", line 244, in wrapped
    raise CommandInvokeError(exc) from exc
discord.ext.commands.errors.CommandInvokeError: Command raised an exception: Forbidden: 403 Forbidden (error code: 50001): Missing Access
[2023-07-07 23:28:13] [DEBUG   ] discord.client: on_ready has successfully been registered as an event
[2023-07-07 23:28:13] [DEBUG   ] discord.client: on_guild_join has successfully been registered as an event
[2023-07-07 23:28:13] [DEBUG   ] discord.client: on_member_join has successfully been registered as an event
[2023-07-07 23:28:13] [INFO    ] discord.client: logging in using static token
[2023-07-07 23:28:15] [INFO    ] discord.gateway: Shard ID None has connected to Gateway (Session ID: c1b01e93ba8e830d94b933a1c1b73a13).
[2023-07-07 23:28:17] [INFO    ] discord: Logged in as ajoke#0521 (ID: 1123604895300329502).
[2023-07-07 23:29:04] [INFO    ] discord: Test Server-1124338606140563629 has just been added.
[2023-07-07 23:29:43] [INFO    ] discord: Stopped bot
[2023-07-07 23:29:43] [ERROR   ] discord.ext.commands.bot: Ignoring exception in command stop
Traceback (most recent call last):
  File "C:\Users\Victor Momodu\Documents\Programming\Software Engineering\Code\DiscordManager\.venv\lib\site-packages\discord\ext\commands\core.py", line 235, in wrapped
    ret = await coro(*args, **kwargs)
  File "c:\Users\Victor Momodu\Documents\Programming\Software Engineering\Code\DiscordManager\event_listener.py", line 67, in stop
    await bot.logout()
AttributeError: 'Bot' object has no attribute 'logout'

The above exception was the direct cause of the following exception:

Traceback (most recent call last):
  File "C:\Users\Victor Momodu\Documents\Programming\Software Engineering\Code\DiscordManager\.venv\lib\site-packages\discord\ext\commands\bot.py", line 1350, in invoke
    await ctx.command.invoke(ctx)
  File "C:\Users\Victor Momodu\Documents\Programming\Software Engineering\Code\DiscordManager\.venv\lib\site-packages\discord\ext\commands\core.py", line 1029, in invoke
    await injected(*ctx.args, **ctx.kwargs)  # type: ignore
  File "C:\Users\Victor Momodu\Documents\Programming\Software Engineering\Code\DiscordManager\.venv\lib\site-packages\discord\ext\commands\core.py", line 244, in wrapped
    raise CommandInvokeError(exc) from exc
discord.ext.commands.errors.CommandInvokeError: Command raised an exception: AttributeError: 'Bot' object has no attribute 'logout'
[2023-07-08 07:21:01] [DEBUG   ] discord.client: on_ready has successfully been registered as an event
[2023-07-08 07:21:01] [DEBUG   ] discord.client: on_guild_join has successfully been registered as an event
[2023-07-08 07:21:01] [DEBUG   ] discord.client: on_member_join has successfully been registered as an event
[2023-07-08 07:21:01] [INFO    ] discord.client: logging in using static token
[2023-07-08 07:21:04] [INFO    ] discord.gateway: Shard ID None has connected to Gateway (Session ID: 1bdaf0745a1baa015d4d81bfac1bf0bb).
[2023-07-08 07:21:06] [INFO    ] discord: Logged in as ajoke#0521 (ID: 1123604895300329502).
[2023-07-08 07:22:28] [INFO    ] discord: Test Server-1124338606140563629 has just been added.
[2023-07-08 07:22:28] [ERROR   ] discord.client: Ignoring exception in on_guild_join
Traceback (most recent call last):
  File "C:\Users\Victor Momodu\Documents\Programming\Software Engineering\Code\DiscordManager\.venv\lib\site-packages\discord\client.py", line 441, in _run_event
    await coro(*args, **kwargs)
  File "c:\Users\Victor Momodu\Documents\Programming\Software Engineering\Code\DiscordManager\event_listener.py", line 50, in on_guild_join
    guild.send(
AttributeError: 'Guild' object has no attribute 'send'
[2023-07-08 07:49:12] [DEBUG   ] discord.client: on_ready has successfully been registered as an event
[2023-07-08 07:49:12] [DEBUG   ] discord.client: on_guild_join has successfully been registered as an event
[2023-07-08 07:49:12] [DEBUG   ] discord.client: on_member_join has successfully been registered as an event
[2023-07-08 07:49:12] [INFO    ] discord.client: logging in using static token
[2023-07-08 07:49:14] [INFO    ] discord.gateway: Shard ID None has connected to Gateway (Session ID: 48020ded4155eb50eeedcdeb0d70b4a2).
[2023-07-08 07:49:16] [INFO    ] discord: Logged in as ajoke#0521 (ID: 1123604895300329502).
[2023-07-08 07:58:19] [DEBUG   ] discord.client: on_ready has successfully been registered as an event
[2023-07-08 07:58:19] [DEBUG   ] discord.client: on_guild_join has successfully been registered as an event
[2023-07-08 07:58:19] [DEBUG   ] discord.client: on_member_join has successfully been registered as an event
[2023-07-08 07:58:19] [INFO    ] discord.client: logging in using static token
[2023-07-08 07:58:21] [INFO    ] discord.gateway: Shard ID None has connected to Gateway (Session ID: 3d133c12be773777136934a12704c3c2).
[2023-07-08 07:58:23] [INFO    ] discord: Logged in as ajoke#0521 (ID: 1123604895300329502).
[2023-07-08 08:00:26] [DEBUG   ] discord.client: on_ready has successfully been registered as an event
[2023-07-08 08:00:26] [DEBUG   ] discord.client: on_guild_join has successfully been registered as an event
[2023-07-08 08:00:26] [DEBUG   ] discord.client: on_member_join has successfully been registered as an event
[2023-07-08 08:00:26] [INFO    ] discord.client: logging in using static token
[2023-07-08 08:00:27] [INFO    ] discord.gateway: Shard ID None has connected to Gateway (Session ID: e987a82940983e1c579081c3845d1b60).
[2023-07-08 08:00:29] [INFO    ] discord: Logged in as ajoke#0521 (ID: 1123604895300329502).
[2023-07-08 08:03:23] [DEBUG   ] discord.client: on_ready has successfully been registered as an event
[2023-07-08 08:03:23] [DEBUG   ] discord.client: on_guild_join has successfully been registered as an event
[2023-07-08 08:03:23] [DEBUG   ] discord.client: on_member_join has successfully been registered as an event
[2023-07-08 08:03:23] [INFO    ] discord.client: logging in using static token
[2023-07-08 08:03:25] [INFO    ] discord.gateway: Shard ID None has connected to Gateway (Session ID: 5152ea17be0bd2211a11ae3507f1f988).
[2023-07-08 08:03:27] [INFO    ] discord: Logged in as ajoke#0521 (ID: 1123604895300329502).
[2023-07-08 08:04:22] [ERROR   ] discord.ext.commands.bot: Ignoring exception in command None
discord.ext.commands.errors.CommandNotFound: Command "guild_channel" is not found
[2023-07-08 08:07:33] [DEBUG   ] discord.client: on_ready has successfully been registered as an event
[2023-07-08 08:07:33] [DEBUG   ] discord.client: on_guild_join has successfully been registered as an event
[2023-07-08 08:07:33] [DEBUG   ] discord.client: on_member_join has successfully been registered as an event
[2023-07-08 08:07:33] [INFO    ] discord.client: logging in using static token
[2023-07-08 08:07:35] [INFO    ] discord.gateway: Shard ID None has connected to Gateway (Session ID: 6aa6c8c5c0bb053c0e9cadc8010d2e18).
[2023-07-08 08:07:37] [INFO    ] discord: Logged in as ajoke#0521 (ID: 1123604895300329502).
[2023-07-08 08:09:48] [DEBUG   ] discord.client: on_ready has successfully been registered as an event
[2023-07-08 08:09:48] [DEBUG   ] discord.client: on_guild_join has successfully been registered as an event
[2023-07-08 08:09:48] [DEBUG   ] discord.client: on_member_join has successfully been registered as an event
[2023-07-08 08:09:48] [INFO    ] discord.client: logging in using static token
[2023-07-08 08:09:50] [INFO    ] discord.gateway: Shard ID None has connected to Gateway (Session ID: af089e5efd5ef0266a2e1f66e36163cc).
[2023-07-08 08:09:52] [INFO    ] discord: Logged in as ajoke#0521 (ID: 1123604895300329502).
[2023-07-08 08:10:40] [DEBUG   ] discord.client: on_ready has successfully been registered as an event
[2023-07-08 08:10:40] [DEBUG   ] discord.client: on_guild_join has successfully been registered as an event
[2023-07-08 08:10:40] [DEBUG   ] discord.client: on_member_join has successfully been registered as an event
[2023-07-08 08:10:40] [INFO    ] discord.client: logging in using static token
[2023-07-08 08:10:42] [INFO    ] discord.gateway: Shard ID None has connected to Gateway (Session ID: 5a482f0c8a9d64a64419040fe5aae7ec).
[2023-07-08 08:10:44] [INFO    ] discord: Logged in as ajoke#0521 (ID: 1123604895300329502).
[2023-07-08 08:13:12] [DEBUG   ] discord.client: on_ready has successfully been registered as an event
[2023-07-08 08:13:12] [DEBUG   ] discord.client: on_guild_join has successfully been registered as an event
[2023-07-08 08:13:12] [DEBUG   ] discord.client: on_member_join has successfully been registered as an event
[2023-07-08 08:13:12] [INFO    ] discord.client: logging in using static token
[2023-07-08 08:13:14] [INFO    ] discord.gateway: Shard ID None has connected to Gateway (Session ID: ef0af3f05227cce849b482b8d13fe237).
[2023-07-08 08:13:16] [INFO    ] discord: Logged in as ajoke#0521 (ID: 1123604895300329502).
[2023-07-08 08:16:28] [DEBUG   ] discord.client: on_ready has successfully been registered as an event
[2023-07-08 08:16:28] [DEBUG   ] discord.client: on_guild_join has successfully been registered as an event
[2023-07-08 08:16:28] [DEBUG   ] discord.client: on_member_join has successfully been registered as an event
[2023-07-08 08:16:28] [INFO    ] discord.client: logging in using static token
[2023-07-08 08:16:30] [INFO    ] discord.gateway: Shard ID None has connected to Gateway (Session ID: 793e137f53471fc035d3e2f0d6553329).
[2023-07-08 08:16:32] [INFO    ] discord: Logged in as ajoke#0521 (ID: 1123604895300329502).
[2023-07-08 08:20:40] [DEBUG   ] discord.client: on_ready has successfully been registered as an event
[2023-07-08 08:20:40] [DEBUG   ] discord.client: on_guild_join has successfully been registered as an event
[2023-07-08 08:20:40] [DEBUG   ] discord.client: on_member_join has successfully been registered as an event
[2023-07-08 08:20:40] [INFO    ] discord.client: logging in using static token
[2023-07-08 08:20:42] [INFO    ] discord.gateway: Shard ID None has connected to Gateway (Session ID: d2bf19234e11066f53e1be34b0152b1e).
[2023-07-08 08:20:44] [INFO    ] discord: Logged in as ajoke#0521 (ID: 1123604895300329502).
[2023-07-08 08:52:00] [DEBUG   ] discord.client: on_ready has successfully been registered as an event
[2023-07-08 08:52:00] [DEBUG   ] discord.client: on_guild_join has successfully been registered as an event
[2023-07-08 08:52:00] [DEBUG   ] discord.client: on_member_join has successfully been registered as an event
[2023-07-08 08:52:00] [INFO    ] discord.client: logging in using static token
[2023-07-08 08:52:02] [INFO    ] discord.gateway: Shard ID None has connected to Gateway (Session ID: cefbaea4c08fcf5f4fc4c85a98621b70).
[2023-07-08 08:52:04] [INFO    ] discord: Logged in as ajoke#0521 (ID: 1123604895300329502).
[2023-07-08 08:53:55] [DEBUG   ] discord.client: on_ready has successfully been registered as an event
[2023-07-08 08:53:55] [DEBUG   ] discord.client: on_guild_join has successfully been registered as an event
[2023-07-08 08:53:55] [DEBUG   ] discord.client: on_member_join has successfully been registered as an event
[2023-07-08 08:53:55] [INFO    ] discord.client: logging in using static token
[2023-07-08 08:53:57] [INFO    ] discord.gateway: Shard ID None has connected to Gateway (Session ID: eef1fc089e85c2328a7f10b2315969be).
[2023-07-08 08:53:59] [INFO    ] discord: Logged in as ajoke#0521 (ID: 1123604895300329502).
[2023-07-11 00:43:08] [DEBUG   ] discord.client: on_ready has successfully been registered as an event
[2023-07-11 00:43:08] [DEBUG   ] discord.client: on_guild_join has successfully been registered as an event
[2023-07-11 00:43:08] [DEBUG   ] discord.client: on_member_join has successfully been registered as an event
[2023-07-11 00:43:08] [INFO    ] discord.client: logging in using static token
[2023-07-11 00:43:10] [INFO    ] discord.gateway: Shard ID None has connected to Gateway (Session ID: 30bd4a9116fb47688d1e9c462a2ebff6).
[2023-07-11 00:43:12] [INFO    ] discord: Logged in as ajoke#0521 (ID: 1123604895300329502).
[2023-07-11 00:43:25] [ERROR   ] discord.ext.commands.bot: Ignoring exception in command form
Traceback (most recent call last):
  File "C:\Users\Victor Momodu\Documents\Programming\Software Engineering\Code\DiscordManager\.venv\lib\site-packages\discord\ext\commands\core.py", line 235, in wrapped
    ret = await coro(*args, **kwargs)
  File "c:\Users\Victor Momodu\Documents\Programming\Software Engineering\Code\DiscordManager\event_listener.py", line 113, in form
    form_url = ctx.content.split()[1]
AttributeError: 'Context' object has no attribute 'content'

The above exception was the direct cause of the following exception:

Traceback (most recent call last):
  File "C:\Users\Victor Momodu\Documents\Programming\Software Engineering\Code\DiscordManager\.venv\lib\site-packages\discord\ext\commands\bot.py", line 1350, in invoke
    await ctx.command.invoke(ctx)
  File "C:\Users\Victor Momodu\Documents\Programming\Software Engineering\Code\DiscordManager\.venv\lib\site-packages\discord\ext\commands\core.py", line 1029, in invoke
    await injected(*ctx.args, **ctx.kwargs)  # type: ignore
  File "C:\Users\Victor Momodu\Documents\Programming\Software Engineering\Code\DiscordManager\.venv\lib\site-packages\discord\ext\commands\core.py", line 244, in wrapped
    raise CommandInvokeError(exc) from exc
discord.ext.commands.errors.CommandInvokeError: Command raised an exception: AttributeError: 'Context' object has no attribute 'content'
[2023-07-11 01:23:33] [DEBUG   ] discord.client: on_ready has successfully been registered as an event
[2023-07-11 01:23:33] [DEBUG   ] discord.client: on_guild_join has successfully been registered as an event
[2023-07-11 01:23:33] [DEBUG   ] discord.client: on_member_join has successfully been registered as an event
[2023-07-11 01:23:33] [DEBUG   ] discord.client: on_message has successfully been registered as an event
[2023-07-11 01:23:33] [INFO    ] discord.client: logging in using static token
[2023-07-11 01:23:36] [INFO    ] discord.gateway: Shard ID None has connected to Gateway (Session ID: 9057fd2ef7121bd7c16b44a3f7af2865).
[2023-07-11 01:23:38] [INFO    ] discord: Logged in as ajoke#0521 (ID: 1123604895300329502).
[2023-07-11 01:23:49] [ERROR   ] discord.client: Ignoring exception in on_message
Traceback (most recent call last):
  File "C:\Users\Victor Momodu\Documents\Programming\Software Engineering\Code\DiscordManager\.venv\lib\site-packages\discord\client.py", line 441, in _run_event
    await coro(*args, **kwargs)
  File "c:\Users\Victor Momodu\Documents\Programming\Software Engineering\Code\DiscordManager\event_listener.py", line 84, in on_message
    Button(style="green"),
TypeError: Button.__init__() got an unexpected keyword argument 'style'
[2023-07-11 01:25:44] [DEBUG   ] discord.client: on_ready has successfully been registered as an event
[2023-07-11 01:25:44] [DEBUG   ] discord.client: on_guild_join has successfully been registered as an event
[2023-07-11 01:25:44] [DEBUG   ] discord.client: on_member_join has successfully been registered as an event
[2023-07-11 01:25:44] [DEBUG   ] discord.client: on_message has successfully been registered as an event
[2023-07-11 01:25:44] [INFO    ] discord.client: logging in using static token
[2023-07-11 01:25:46] [INFO    ] discord.gateway: Shard ID None has connected to Gateway (Session ID: bdf4e836035fb09e1845513144bd2ccf).
[2023-07-11 01:25:48] [INFO    ] discord: Logged in as ajoke#0521 (ID: 1123604895300329502).
[2023-07-11 01:25:52] [ERROR   ] discord.client: Ignoring exception in on_message
Traceback (most recent call last):
  File "C:\Users\Victor Momodu\Documents\Programming\Software Engineering\Code\DiscordManager\.venv\lib\site-packages\discord\client.py", line 441, in _run_event
    await coro(*args, **kwargs)
  File "c:\Users\Victor Momodu\Documents\Programming\Software Engineering\Code\DiscordManager\event_listener.py", line 84, in on_message
    Button(style=1),
TypeError: Button.__init__() got an unexpected keyword argument 'style'
[2023-07-11 01:29:20] [DEBUG   ] discord.client: on_ready has successfully been registered as an event
[2023-07-11 01:29:20] [DEBUG   ] discord.client: on_guild_join has successfully been registered as an event
[2023-07-11 01:29:20] [DEBUG   ] discord.client: on_member_join has successfully been registered as an event
[2023-07-11 01:29:20] [DEBUG   ] discord.client: on_message has successfully been registered as an event
[2023-07-11 01:29:20] [INFO    ] discord.client: logging in using static token
[2023-07-11 01:29:22] [INFO    ] discord.gateway: Shard ID None has connected to Gateway (Session ID: 651e4d6c0c477065f578b3e1fa6d8872).
[2023-07-11 01:29:24] [INFO    ] discord: Logged in as ajoke#0521 (ID: 1123604895300329502).
[2023-07-11 01:29:28] [ERROR   ] discord.client: Ignoring exception in on_message
Traceback (most recent call last):
  File "C:\Users\Victor Momodu\Documents\Programming\Software Engineering\Code\DiscordManager\.venv\lib\site-packages\discord\client.py", line 441, in _run_event
    await coro(*args, **kwargs)
  File "c:\Users\Victor Momodu\Documents\Programming\Software Engineering\Code\DiscordManager\event_listener.py", line 85, in on_message
    Button(style=ButtonStyle(1))
TypeError: Button.__init__() got an unexpected keyword argument 'style'
[2023-07-11 01:30:01] [DEBUG   ] discord.client: on_ready has successfully been registered as an event
[2023-07-11 01:30:01] [DEBUG   ] discord.client: on_guild_join has successfully been registered as an event
[2023-07-11 01:30:01] [DEBUG   ] discord.client: on_member_join has successfully been registered as an event
[2023-07-11 01:30:01] [DEBUG   ] discord.client: on_message has successfully been registered as an event
[2023-07-11 01:30:01] [INFO    ] discord.client: logging in using static token
[2023-07-11 01:30:03] [INFO    ] discord.gateway: Shard ID None has connected to Gateway (Session ID: 427d7bada3c4aaf4b1607eaf50d81273).
[2023-07-11 01:30:05] [INFO    ] discord: Logged in as ajoke#0521 (ID: 1123604895300329502).
[2023-07-11 01:30:07] [ERROR   ] discord.client: Ignoring exception in on_message
Traceback (most recent call last):
  File "C:\Users\Victor Momodu\Documents\Programming\Software Engineering\Code\DiscordManager\.venv\lib\site-packages\discord\client.py", line 441, in _run_event
    await coro(*args, **kwargs)
  File "c:\Users\Victor Momodu\Documents\Programming\Software Engineering\Code\DiscordManager\event_listener.py", line 85, in on_message
    Button(ButtonStyle(1))
  File "C:\Users\Victor Momodu\Documents\Programming\Software Engineering\Code\DiscordManager\.venv\lib\site-packages\discord\components.py", line 184, in __init__
    self.style: ButtonStyle = try_enum(ButtonStyle, data['style'])
TypeError: tuple indices must be integers or slices, not str
[2023-07-11 01:38:29] [DEBUG   ] discord.client: on_ready has successfully been registered as an event
[2023-07-11 01:38:29] [DEBUG   ] discord.client: on_guild_join has successfully been registered as an event
[2023-07-11 01:38:29] [DEBUG   ] discord.client: on_member_join has successfully been registered as an event
[2023-07-11 01:38:29] [DEBUG   ] discord.client: on_message has successfully been registered as an event
[2023-07-11 01:38:29] [INFO    ] discord.client: logging in using static token
[2023-07-11 01:38:52] [INFO    ] discord.gateway: Shard ID None has connected to Gateway (Session ID: 70031f73163726d70a931b3001e5f44a).
[2023-07-11 01:38:54] [INFO    ] discord: Logged in as ajoke#0521 (ID: 1123604895300329502).
[2023-07-11 01:38:58] [ERROR   ] discord.client: Ignoring exception in on_message
Traceback (most recent call last):
  File "C:\Users\Victor Momodu\Documents\Programming\Software Engineering\Code\DiscordManager\.venv\lib\site-packages\discord\enums.py", line 158, in __call__
    return cls._enum_value_map_[value]
TypeError: unhashable type: 'dict'

During handling of the above exception, another exception occurred:

Traceback (most recent call last):
  File "C:\Users\Victor Momodu\Documents\Programming\Software Engineering\Code\DiscordManager\.venv\lib\site-packages\discord\client.py", line 441, in _run_event
    await coro(*args, **kwargs)
  File "c:\Users\Victor Momodu\Documents\Programming\Software Engineering\Code\DiscordManager\event_listener.py", line 85, in on_message
    Button(ButtonStyle({"style": "primary"}))
  File "C:\Users\Victor Momodu\Documents\Programming\Software Engineering\Code\DiscordManager\.venv\lib\site-packages\discord\enums.py", line 160, in __call__
    raise ValueError(f"{value!r} is not a valid {cls.__name__}")
ValueError: {'style': 'primary'} is not a valid ButtonStyle
[2023-07-11 01:39:51] [DEBUG   ] discord.client: on_ready has successfully been registered as an event
[2023-07-11 01:39:51] [DEBUG   ] discord.client: on_guild_join has successfully been registered as an event
[2023-07-11 01:39:51] [DEBUG   ] discord.client: on_member_join has successfully been registered as an event
[2023-07-11 01:39:51] [DEBUG   ] discord.client: on_message has successfully been registered as an event
[2023-07-11 01:39:51] [INFO    ] discord.client: logging in using static token
[2023-07-11 01:40:14] [INFO    ] discord.gateway: Shard ID None has connected to Gateway (Session ID: 69759d1d78bf63f5ffeb3c9eb760d31e).
[2023-07-11 01:40:16] [INFO    ] discord: Logged in as ajoke#0521 (ID: 1123604895300329502).
[2023-07-11 01:40:22] [ERROR   ] discord.client: Ignoring exception in on_message
Traceback (most recent call last):
  File "C:\Users\Victor Momodu\Documents\Programming\Software Engineering\Code\DiscordManager\.venv\lib\site-packages\discord\client.py", line 441, in _run_event
    await coro(*args, **kwargs)
  File "c:\Users\Victor Momodu\Documents\Programming\Software Engineering\Code\DiscordManager\event_listener.py", line 88, in on_message
    await message.channel.send(
TypeError: Messageable.send() got an unexpected keyword argument 'components'
[2023-07-11 02:01:38] [DEBUG   ] discord.client: on_ready has successfully been registered as an event
[2023-07-11 02:01:38] [DEBUG   ] discord.client: on_guild_join has successfully been registered as an event
[2023-07-11 02:01:38] [DEBUG   ] discord.client: on_member_join has successfully been registered as an event
[2023-07-11 02:01:38] [INFO    ] discord.client: logging in using static token
[2023-07-11 02:01:40] [INFO    ] discord.gateway: Shard ID None has connected to Gateway (Session ID: 90f415c535131d5efcbadb24ced067ed).
[2023-07-11 02:01:42] [INFO    ] discord: Logged in as ajoke#0521 (ID: 1123604895300329502).
[2023-07-11 02:01:46] [ERROR   ] discord.ext.commands.bot: Ignoring exception in command button
Traceback (most recent call last):
  File "C:\Users\Victor Momodu\Documents\Programming\Software Engineering\Code\DiscordManager\.venv\lib\site-packages\discord\ext\commands\core.py", line 235, in wrapped
    ret = await coro(*args, **kwargs)
  File "c:\Users\Victor Momodu\Documents\Programming\Software Engineering\Code\DiscordManager\event_listener.py", line 102, in button
    await interaction.response.send_model(Questionnaire())
AttributeError: 'Context' object has no attribute 'response'

The above exception was the direct cause of the following exception:

Traceback (most recent call last):
  File "C:\Users\Victor Momodu\Documents\Programming\Software Engineering\Code\DiscordManager\.venv\lib\site-packages\discord\ext\commands\bot.py", line 1350, in invoke
    await ctx.command.invoke(ctx)
  File "C:\Users\Victor Momodu\Documents\Programming\Software Engineering\Code\DiscordManager\.venv\lib\site-packages\discord\ext\commands\core.py", line 1029, in invoke
    await injected(*ctx.args, **ctx.kwargs)  # type: ignore
  File "C:\Users\Victor Momodu\Documents\Programming\Software Engineering\Code\DiscordManager\.venv\lib\site-packages\discord\ext\commands\core.py", line 244, in wrapped
    raise CommandInvokeError(exc) from exc
discord.ext.commands.errors.CommandInvokeError: Command raised an exception: AttributeError: 'Context' object has no attribute 'response'
[2023-07-11 02:13:05] [INFO    ] discord.client: logging in using static token
[2023-07-11 02:13:08] [INFO    ] discord.gateway: Shard ID None has connected to Gateway (Session ID: b359f91ba5c87a802ab417dd867dfdbb).
[2023-07-11 02:13:10] [INFO    ] discord: Logged in as ajoke#0521 (ID: 1123604895300329502).
[2023-07-11 02:13:22] [ERROR   ] discord.client: Attempting a reconnect in 0.90s
Traceback (most recent call last):
  File "C:\Users\Victor Momodu\Documents\Programming\Software Engineering\Code\DiscordManager\.venv\lib\site-packages\aiohttp\connector.py", line 1152, in _create_direct_connection
    hosts = await asyncio.shield(host_resolved)
  File "C:\Users\Victor Momodu\Documents\Programming\Software Engineering\Code\DiscordManager\.venv\lib\site-packages\aiohttp\connector.py", line 874, in _resolve_host
    addrs = await self._resolver.resolve(host, port, family=self._family)
  File "C:\Users\Victor Momodu\Documents\Programming\Software Engineering\Code\DiscordManager\.venv\lib\site-packages\aiohttp\resolver.py", line 33, in resolve
    infos = await self._loop.getaddrinfo(
  File "C:\Users\Victor Momodu\AppData\Local\Programs\Python\Python310\lib\asyncio\base_events.py", line 860, in getaddrinfo
    return await self.run_in_executor(
  File "C:\Users\Victor Momodu\AppData\Local\Programs\Python\Python310\lib\concurrent\futures\thread.py", line 58, in run
    result = self.fn(*self.args, **self.kwargs)
  File "C:\Users\Victor Momodu\AppData\Local\Programs\Python\Python310\lib\socket.py", line 955, in getaddrinfo
    for res in _socket.getaddrinfo(host, port, family, type, proto, flags):
socket.gaierror: [Errno 11001] getaddrinfo failed

The above exception was the direct cause of the following exception:

Traceback (most recent call last):
  File "C:\Users\Victor Momodu\Documents\Programming\Software Engineering\Code\DiscordManager\.venv\lib\site-packages\discord\client.py", line 656, in connect
    self.ws = await asyncio.wait_for(coro, timeout=60.0)
  File "C:\Users\Victor Momodu\AppData\Local\Programs\Python\Python310\lib\asyncio\tasks.py", line 445, in wait_for
    return fut.result()
  File "C:\Users\Victor Momodu\Documents\Programming\Software Engineering\Code\DiscordManager\.venv\lib\site-packages\discord\gateway.py", line 372, in from_client
    socket = await client.http.ws_connect(str(url))
  File "C:\Users\Victor Momodu\Documents\Programming\Software Engineering\Code\DiscordManager\.venv\lib\site-packages\discord\http.py", line 537, in ws_connect
    return await self.__session.ws_connect(url, **kwargs)
  File "C:\Users\Victor Momodu\Documents\Programming\Software Engineering\Code\DiscordManager\.venv\lib\site-packages\aiohttp\client.py", line 779, in _ws_connect
    resp = await self.request(
  File "C:\Users\Victor Momodu\Documents\Programming\Software Engineering\Code\DiscordManager\.venv\lib\site-packages\aiohttp\client.py", line 536, in _request
    conn = await self._connector.connect(
  File "C:\Users\Victor Momodu\Documents\Programming\Software Engineering\Code\DiscordManager\.venv\lib\site-packages\aiohttp\connector.py", line 540, in connect
    proto = await self._create_connection(req, traces, timeout)
  File "C:\Users\Victor Momodu\Documents\Programming\Software Engineering\Code\DiscordManager\.venv\lib\site-packages\aiohttp\connector.py", line 901, in _create_connection
    _, proto = await self._create_direct_connection(req, traces, timeout)
  File "C:\Users\Victor Momodu\Documents\Programming\Software Engineering\Code\DiscordManager\.venv\lib\site-packages\aiohttp\connector.py", line 1166, in _create_direct_connection
    raise ClientConnectorError(req.connection_key, exc) from exc
aiohttp.client_exceptions.ClientConnectorError: Cannot connect to host gateway-us-east1-c.discord.gg:443 ssl:default [getaddrinfo failed]
[2023-07-11 02:13:24] [INFO    ] discord.gateway: Shard ID None has successfully RESUMED session b359f91ba5c87a802ab417dd867dfdbb.
[2023-07-11 02:18:34] [INFO    ] discord.client: logging in using static token
[2023-07-11 02:18:36] [INFO    ] discord.gateway: Shard ID None has connected to Gateway (Session ID: 1e186b7d73b736c3745f3395d454095e).
[2023-07-11 02:18:38] [INFO    ] discord: Logged in as ajoke#0521 (ID: 1123604895300329502).
[2023-07-11 02:20:42] [INFO    ] discord.client: logging in using static token
[2023-07-11 02:20:44] [INFO    ] discord.gateway: Shard ID None has connected to Gateway (Session ID: 7785f981c7d7d3ddfb0ff70d58e60758).
[2023-07-11 02:20:46] [INFO    ] discord: Logged in as ajoke#0521 (ID: 1123604895300329502).
[2023-07-11 02:25:03] [INFO    ] discord.client: logging in using static token
[2023-07-11 02:28:19] [INFO    ] discord.client: logging in using static token
[2023-07-11 07:32:42] [DEBUG   ] discord.client: on_ready has successfully been registered as an event
[2023-07-11 07:32:42] [DEBUG   ] discord.client: on_guild_join has successfully been registered as an event
[2023-07-11 07:32:42] [DEBUG   ] discord.client: on_member_join has successfully been registered as an event
[2023-07-11 07:32:42] [INFO    ] discord.client: logging in using static token
[2023-07-11 07:32:45] [INFO    ] discord.gateway: Shard ID None has connected to Gateway (Session ID: e9f08fb64eaf013c3ae2b886ed27b254).
[2023-07-11 07:32:47] [INFO    ] discord: Logged in as ajoke#0521 (ID: 1123604895300329502).
[2023-07-11 07:32:55] [ERROR   ] discord.client: Attempting a reconnect in 1.11s
Traceback (most recent call last):
  File "C:\Users\Victor Momodu\Documents\Programming\Software Engineering\Code\DiscordManager\.venv\lib\site-packages\aiohttp\connector.py", line 1152, in _create_direct_connection
    hosts = await asyncio.shield(host_resolved)
  File "C:\Users\Victor Momodu\Documents\Programming\Software Engineering\Code\DiscordManager\.venv\lib\site-packages\aiohttp\connector.py", line 874, in _resolve_host
    addrs = await self._resolver.resolve(host, port, family=self._family)
  File "C:\Users\Victor Momodu\Documents\Programming\Software Engineering\Code\DiscordManager\.venv\lib\site-packages\aiohttp\resolver.py", line 33, in resolve
    infos = await self._loop.getaddrinfo(
  File "C:\Users\Victor Momodu\AppData\Local\Programs\Python\Python310\lib\asyncio\base_events.py", line 860, in getaddrinfo
    return await self.run_in_executor(
  File "C:\Users\Victor Momodu\AppData\Local\Programs\Python\Python310\lib\concurrent\futures\thread.py", line 58, in run
    result = self.fn(*self.args, **self.kwargs)
  File "C:\Users\Victor Momodu\AppData\Local\Programs\Python\Python310\lib\socket.py", line 955, in getaddrinfo
    for res in _socket.getaddrinfo(host, port, family, type, proto, flags):
socket.gaierror: [Errno 11001] getaddrinfo failed

The above exception was the direct cause of the following exception:

Traceback (most recent call last):
  File "C:\Users\Victor Momodu\Documents\Programming\Software Engineering\Code\DiscordManager\.venv\lib\site-packages\discord\client.py", line 656, in connect
    self.ws = await asyncio.wait_for(coro, timeout=60.0)
  File "C:\Users\Victor Momodu\AppData\Local\Programs\Python\Python310\lib\asyncio\tasks.py", line 445, in wait_for
    return fut.result()
  File "C:\Users\Victor Momodu\Documents\Programming\Software Engineering\Code\DiscordManager\.venv\lib\site-packages\discord\gateway.py", line 372, in from_client
    socket = await client.http.ws_connect(str(url))
  File "C:\Users\Victor Momodu\Documents\Programming\Software Engineering\Code\DiscordManager\.venv\lib\site-packages\discord\http.py", line 537, in ws_connect
    return await self.__session.ws_connect(url, **kwargs)
  File "C:\Users\Victor Momodu\Documents\Programming\Software Engineering\Code\DiscordManager\.venv\lib\site-packages\aiohttp\client.py", line 779, in _ws_connect
    resp = await self.request(
  File "C:\Users\Victor Momodu\Documents\Programming\Software Engineering\Code\DiscordManager\.venv\lib\site-packages\aiohttp\client.py", line 536, in _request
    conn = await self._connector.connect(
  File "C:\Users\Victor Momodu\Documents\Programming\Software Engineering\Code\DiscordManager\.venv\lib\site-packages\aiohttp\connector.py", line 540, in connect
    proto = await self._create_connection(req, traces, timeout)
  File "C:\Users\Victor Momodu\Documents\Programming\Software Engineering\Code\DiscordManager\.venv\lib\site-packages\aiohttp\connector.py", line 901, in _create_connection
    _, proto = await self._create_direct_connection(req, traces, timeout)
  File "C:\Users\Victor Momodu\Documents\Programming\Software Engineering\Code\DiscordManager\.venv\lib\site-packages\aiohttp\connector.py", line 1166, in _create_direct_connection
    raise ClientConnectorError(req.connection_key, exc) from exc
aiohttp.client_exceptions.ClientConnectorError: Cannot connect to host gateway-us-east1-b.discord.gg:443 ssl:default [getaddrinfo failed]
[2023-07-11 07:32:57] [INFO    ] discord.gateway: Shard ID None has successfully RESUMED session e9f08fb64eaf013c3ae2b886ed27b254.
[2023-07-11 07:33:00] [ERROR   ] discord.client: Attempting a reconnect in 2.60s
Traceback (most recent call last):
  File "C:\Users\Victor Momodu\Documents\Programming\Software Engineering\Code\DiscordManager\.venv\lib\site-packages\aiohttp\connector.py", line 980, in _wrap_create_connection
    return await self._loop.create_connection(*args, **kwargs)  # type: ignore[return-value]  # noqa
  File "C:\Users\Victor Momodu\AppData\Local\Programs\Python\Python310\lib\asyncio\base_events.py", line 1064, in create_connection
    raise exceptions[0]
  File "C:\Users\Victor Momodu\AppData\Local\Programs\Python\Python310\lib\asyncio\base_events.py", line 1049, in create_connection
    sock = await self._connect_sock(
  File "C:\Users\Victor Momodu\AppData\Local\Programs\Python\Python310\lib\asyncio\base_events.py", line 960, in _connect_sock
    await self.sock_connect(sock, address)
  File "C:\Users\Victor Momodu\AppData\Local\Programs\Python\Python310\lib\asyncio\proactor_events.py", line 705, in sock_connect
    return await self._proactor.connect(sock, address)
  File "C:\Users\Victor Momodu\AppData\Local\Programs\Python\Python310\lib\asyncio\windows_events.py", line 817, in _poll
    value = callback(transferred, key, ov)
  File "C:\Users\Victor Momodu\AppData\Local\Programs\Python\Python310\lib\asyncio\windows_events.py", line 604, in finish_connect
    ov.getresult()
OSError: [WinError 1232] The network location cannot be reached. For information about network troubleshooting, see Windows Help

The above exception was the direct cause of the following exception:

Traceback (most recent call last):
  File "C:\Users\Victor Momodu\Documents\Programming\Software Engineering\Code\DiscordManager\.venv\lib\site-packages\discord\client.py", line 656, in connect
    self.ws = await asyncio.wait_for(coro, timeout=60.0)
  File "C:\Users\Victor Momodu\AppData\Local\Programs\Python\Python310\lib\asyncio\tasks.py", line 445, in wait_for
    return fut.result()
  File "C:\Users\Victor Momodu\Documents\Programming\Software Engineering\Code\DiscordManager\.venv\lib\site-packages\discord\gateway.py", line 372, in from_client
    socket = await client.http.ws_connect(str(url))
  File "C:\Users\Victor Momodu\Documents\Programming\Software Engineering\Code\DiscordManager\.venv\lib\site-packages\discord\http.py", line 537, in ws_connect
    return await self.__session.ws_connect(url, **kwargs)
  File "C:\Users\Victor Momodu\Documents\Programming\Software Engineering\Code\DiscordManager\.venv\lib\site-packages\aiohttp\client.py", line 779, in _ws_connect
    resp = await self.request(
  File "C:\Users\Victor Momodu\Documents\Programming\Software Engineering\Code\DiscordManager\.venv\lib\site-packages\aiohttp\client.py", line 536, in _request
    conn = await self._connector.connect(
  File "C:\Users\Victor Momodu\Documents\Programming\Software Engineering\Code\DiscordManager\.venv\lib\site-packages\aiohttp\connector.py", line 540, in connect
    proto = await self._create_connection(req, traces, timeout)
  File "C:\Users\Victor Momodu\Documents\Programming\Software Engineering\Code\DiscordManager\.venv\lib\site-packages\aiohttp\connector.py", line 901, in _create_connection
    _, proto = await self._create_direct_connection(req, traces, timeout)
  File "C:\Users\Victor Momodu\Documents\Programming\Software Engineering\Code\DiscordManager\.venv\lib\site-packages\aiohttp\connector.py", line 1206, in _create_direct_connection
    raise last_exc
  File "C:\Users\Victor Momodu\Documents\Programming\Software Engineering\Code\DiscordManager\.venv\lib\site-packages\aiohttp\connector.py", line 1175, in _create_direct_connection
    transp, proto = await self._wrap_create_connection(
  File "C:\Users\Victor Momodu\Documents\Programming\Software Engineering\Code\DiscordManager\.venv\lib\site-packages\aiohttp\connector.py", line 988, in _wrap_create_connection
    raise client_error(req.connection_key, exc) from exc
aiohttp.client_exceptions.ClientConnectorError: Cannot connect to host gateway-us-east1-b.discord.gg:443 ssl:default [The network location cannot be reached. For information about network troubleshooting, see Windows Help]
[2023-07-11 07:33:04] [INFO    ] discord.gateway: Shard ID None has successfully RESUMED session e9f08fb64eaf013c3ae2b886ed27b254.
[2023-07-11 07:33:44] [DEBUG   ] discord.client: on_ready has successfully been registered as an event
[2023-07-11 07:33:44] [DEBUG   ] discord.client: on_guild_join has successfully been registered as an event
[2023-07-11 07:33:44] [DEBUG   ] discord.client: on_member_join has successfully been registered as an event
[2023-07-11 07:33:44] [INFO    ] discord.client: logging in using static token
[2023-07-11 07:33:46] [INFO    ] discord.gateway: Shard ID None has connected to Gateway (Session ID: b29fdab436fac0494ba42fc65400c1e9).
[2023-07-11 07:33:48] [INFO    ] discord: Logged in as ajoke#0521 (ID: 1123604895300329502).
[2023-07-11 07:33:57] [ERROR   ] discord.client: Attempting a reconnect in 0.09s
Traceback (most recent call last):
  File "C:\Users\Victor Momodu\Documents\Programming\Software Engineering\Code\DiscordManager\.venv\lib\site-packages\aiohttp\connector.py", line 1152, in _create_direct_connection
    hosts = await asyncio.shield(host_resolved)
  File "C:\Users\Victor Momodu\Documents\Programming\Software Engineering\Code\DiscordManager\.venv\lib\site-packages\aiohttp\connector.py", line 874, in _resolve_host
    addrs = await self._resolver.resolve(host, port, family=self._family)
  File "C:\Users\Victor Momodu\Documents\Programming\Software Engineering\Code\DiscordManager\.venv\lib\site-packages\aiohttp\resolver.py", line 33, in resolve
    infos = await self._loop.getaddrinfo(
  File "C:\Users\Victor Momodu\AppData\Local\Programs\Python\Python310\lib\asyncio\base_events.py", line 860, in getaddrinfo
    return await self.run_in_executor(
  File "C:\Users\Victor Momodu\AppData\Local\Programs\Python\Python310\lib\concurrent\futures\thread.py", line 58, in run
    result = self.fn(*self.args, **self.kwargs)
  File "C:\Users\Victor Momodu\AppData\Local\Programs\Python\Python310\lib\socket.py", line 955, in getaddrinfo
    for res in _socket.getaddrinfo(host, port, family, type, proto, flags):
socket.gaierror: [Errno 11001] getaddrinfo failed

The above exception was the direct cause of the following exception:

Traceback (most recent call last):
  File "C:\Users\Victor Momodu\Documents\Programming\Software Engineering\Code\DiscordManager\.venv\lib\site-packages\discord\client.py", line 656, in connect
    self.ws = await asyncio.wait_for(coro, timeout=60.0)
  File "C:\Users\Victor Momodu\AppData\Local\Programs\Python\Python310\lib\asyncio\tasks.py", line 445, in wait_for
    return fut.result()
  File "C:\Users\Victor Momodu\Documents\Programming\Software Engineering\Code\DiscordManager\.venv\lib\site-packages\discord\gateway.py", line 372, in from_client
    socket = await client.http.ws_connect(str(url))
  File "C:\Users\Victor Momodu\Documents\Programming\Software Engineering\Code\DiscordManager\.venv\lib\site-packages\discord\http.py", line 537, in ws_connect
    return await self.__session.ws_connect(url, **kwargs)
  File "C:\Users\Victor Momodu\Documents\Programming\Software Engineering\Code\DiscordManager\.venv\lib\site-packages\aiohttp\client.py", line 779, in _ws_connect
    resp = await self.request(
  File "C:\Users\Victor Momodu\Documents\Programming\Software Engineering\Code\DiscordManager\.venv\lib\site-packages\aiohttp\client.py", line 536, in _request
    conn = await self._connector.connect(
  File "C:\Users\Victor Momodu\Documents\Programming\Software Engineering\Code\DiscordManager\.venv\lib\site-packages\aiohttp\connector.py", line 540, in connect
    proto = await self._create_connection(req, traces, timeout)
  File "C:\Users\Victor Momodu\Documents\Programming\Software Engineering\Code\DiscordManager\.venv\lib\site-packages\aiohttp\connector.py", line 901, in _create_connection
    _, proto = await self._create_direct_connection(req, traces, timeout)
  File "C:\Users\Victor Momodu\Documents\Programming\Software Engineering\Code\DiscordManager\.venv\lib\site-packages\aiohttp\connector.py", line 1166, in _create_direct_connection
    raise ClientConnectorError(req.connection_key, exc) from exc
aiohttp.client_exceptions.ClientConnectorError: Cannot connect to host gateway-us-east1-b.discord.gg:443 ssl:default [getaddrinfo failed]
[2023-07-11 07:33:57] [ERROR   ] discord.client: Attempting a reconnect in 1.15s
Traceback (most recent call last):
  File "C:\Users\Victor Momodu\Documents\Programming\Software Engineering\Code\DiscordManager\.venv\lib\site-packages\aiohttp\connector.py", line 1152, in _create_direct_connection
    hosts = await asyncio.shield(host_resolved)
  File "C:\Users\Victor Momodu\Documents\Programming\Software Engineering\Code\DiscordManager\.venv\lib\site-packages\aiohttp\connector.py", line 874, in _resolve_host
    addrs = await self._resolver.resolve(host, port, family=self._family)
  File "C:\Users\Victor Momodu\Documents\Programming\Software Engineering\Code\DiscordManager\.venv\lib\site-packages\aiohttp\resolver.py", line 33, in resolve
    infos = await self._loop.getaddrinfo(
  File "C:\Users\Victor Momodu\AppData\Local\Programs\Python\Python310\lib\asyncio\base_events.py", line 860, in getaddrinfo
    return await self.run_in_executor(
  File "C:\Users\Victor Momodu\AppData\Local\Programs\Python\Python310\lib\concurrent\futures\thread.py", line 58, in run
    result = self.fn(*self.args, **self.kwargs)
  File "C:\Users\Victor Momodu\AppData\Local\Programs\Python\Python310\lib\socket.py", line 955, in getaddrinfo
    for res in _socket.getaddrinfo(host, port, family, type, proto, flags):
socket.gaierror: [Errno 11001] getaddrinfo failed

The above exception was the direct cause of the following exception:

Traceback (most recent call last):
  File "C:\Users\Victor Momodu\Documents\Programming\Software Engineering\Code\DiscordManager\.venv\lib\site-packages\discord\client.py", line 656, in connect
    self.ws = await asyncio.wait_for(coro, timeout=60.0)
  File "C:\Users\Victor Momodu\AppData\Local\Programs\Python\Python310\lib\asyncio\tasks.py", line 445, in wait_for
    return fut.result()
  File "C:\Users\Victor Momodu\Documents\Programming\Software Engineering\Code\DiscordManager\.venv\lib\site-packages\discord\gateway.py", line 372, in from_client
    socket = await client.http.ws_connect(str(url))
  File "C:\Users\Victor Momodu\Documents\Programming\Software Engineering\Code\DiscordManager\.venv\lib\site-packages\discord\http.py", line 537, in ws_connect
    return await self.__session.ws_connect(url, **kwargs)
  File "C:\Users\Victor Momodu\Documents\Programming\Software Engineering\Code\DiscordManager\.venv\lib\site-packages\aiohttp\client.py", line 779, in _ws_connect
    resp = await self.request(
  File "C:\Users\Victor Momodu\Documents\Programming\Software Engineering\Code\DiscordManager\.venv\lib\site-packages\aiohttp\client.py", line 536, in _request
    conn = await self._connector.connect(
  File "C:\Users\Victor Momodu\Documents\Programming\Software Engineering\Code\DiscordManager\.venv\lib\site-packages\aiohttp\connector.py", line 540, in connect
    proto = await self._create_connection(req, traces, timeout)
  File "C:\Users\Victor Momodu\Documents\Programming\Software Engineering\Code\DiscordManager\.venv\lib\site-packages\aiohttp\connector.py", line 901, in _create_connection
    _, proto = await self._create_direct_connection(req, traces, timeout)
  File "C:\Users\Victor Momodu\Documents\Programming\Software Engineering\Code\DiscordManager\.venv\lib\site-packages\aiohttp\connector.py", line 1166, in _create_direct_connection
    raise ClientConnectorError(req.connection_key, exc) from exc
aiohttp.client_exceptions.ClientConnectorError: Cannot connect to host gateway-us-east1-b.discord.gg:443 ssl:default [getaddrinfo failed]
[2023-07-11 07:33:59] [INFO    ] discord.gateway: Shard ID None has successfully RESUMED session b29fdab436fac0494ba42fc65400c1e9.
[2023-07-11 07:34:05] [ERROR   ] discord.client: Attempting a reconnect in 0.86s
Traceback (most recent call last):
  File "C:\Users\Victor Momodu\Documents\Programming\Software Engineering\Code\DiscordManager\.venv\lib\site-packages\aiohttp\connector.py", line 980, in _wrap_create_connection
    return await self._loop.create_connection(*args, **kwargs)  # type: ignore[return-value]  # noqa
  File "C:\Users\Victor Momodu\AppData\Local\Programs\Python\Python310\lib\asyncio\base_events.py", line 1064, in create_connection
    raise exceptions[0]
  File "C:\Users\Victor Momodu\AppData\Local\Programs\Python\Python310\lib\asyncio\base_events.py", line 1049, in create_connection
    sock = await self._connect_sock(
  File "C:\Users\Victor Momodu\AppData\Local\Programs\Python\Python310\lib\asyncio\base_events.py", line 960, in _connect_sock
    await self.sock_connect(sock, address)
  File "C:\Users\Victor Momodu\AppData\Local\Programs\Python\Python310\lib\asyncio\proactor_events.py", line 705, in sock_connect
    return await self._proactor.connect(sock, address)
  File "C:\Users\Victor Momodu\AppData\Local\Programs\Python\Python310\lib\asyncio\windows_events.py", line 817, in _poll
    value = callback(transferred, key, ov)
  File "C:\Users\Victor Momodu\AppData\Local\Programs\Python\Python310\lib\asyncio\windows_events.py", line 604, in finish_connect
    ov.getresult()
OSError: [WinError 1232] The network location cannot be reached. For information about network troubleshooting, see Windows Help

The above exception was the direct cause of the following exception:

Traceback (most recent call last):
  File "C:\Users\Victor Momodu\Documents\Programming\Software Engineering\Code\DiscordManager\.venv\lib\site-packages\discord\client.py", line 656, in connect
    self.ws = await asyncio.wait_for(coro, timeout=60.0)
  File "C:\Users\Victor Momodu\AppData\Local\Programs\Python\Python310\lib\asyncio\tasks.py", line 445, in wait_for
    return fut.result()
  File "C:\Users\Victor Momodu\Documents\Programming\Software Engineering\Code\DiscordManager\.venv\lib\site-packages\discord\gateway.py", line 372, in from_client
    socket = await client.http.ws_connect(str(url))
  File "C:\Users\Victor Momodu\Documents\Programming\Software Engineering\Code\DiscordManager\.venv\lib\site-packages\discord\http.py", line 537, in ws_connect
    return await self.__session.ws_connect(url, **kwargs)
  File "C:\Users\Victor Momodu\Documents\Programming\Software Engineering\Code\DiscordManager\.venv\lib\site-packages\aiohttp\client.py", line 779, in _ws_connect
    resp = await self.request(
  File "C:\Users\Victor Momodu\Documents\Programming\Software Engineering\Code\DiscordManager\.venv\lib\site-packages\aiohttp\client.py", line 536, in _request
    conn = await self._connector.connect(
  File "C:\Users\Victor Momodu\Documents\Programming\Software Engineering\Code\DiscordManager\.venv\lib\site-packages\aiohttp\connector.py", line 540, in connect
    proto = await self._create_connection(req, traces, timeout)
  File "C:\Users\Victor Momodu\Documents\Programming\Software Engineering\Code\DiscordManager\.venv\lib\site-packages\aiohttp\connector.py", line 901, in _create_connection
    _, proto = await self._create_direct_connection(req, traces, timeout)
  File "C:\Users\Victor Momodu\Documents\Programming\Software Engineering\Code\DiscordManager\.venv\lib\site-packages\aiohttp\connector.py", line 1206, in _create_direct_connection
    raise last_exc
  File "C:\Users\Victor Momodu\Documents\Programming\Software Engineering\Code\DiscordManager\.venv\lib\site-packages\aiohttp\connector.py", line 1175, in _create_direct_connection
    transp, proto = await self._wrap_create_connection(
  File "C:\Users\Victor Momodu\Documents\Programming\Software Engineering\Code\DiscordManager\.venv\lib\site-packages\aiohttp\connector.py", line 988, in _wrap_create_connection
    raise client_error(req.connection_key, exc) from exc
aiohttp.client_exceptions.ClientConnectorError: Cannot connect to host gateway-us-east1-b.discord.gg:443 ssl:default [The network location cannot be reached. For information about network troubleshooting, see Windows Help]
[2023-07-11 07:34:07] [INFO    ] discord.gateway: Shard ID None has successfully RESUMED session b29fdab436fac0494ba42fc65400c1e9.
[2023-07-11 07:34:54] [ERROR   ] discord.client: Attempting a reconnect in 5.48s
Traceback (most recent call last):
  File "C:\Users\Victor Momodu\Documents\Programming\Software Engineering\Code\DiscordManager\.venv\lib\site-packages\aiohttp\connector.py", line 1152, in _create_direct_connection
    hosts = await asyncio.shield(host_resolved)
  File "C:\Users\Victor Momodu\Documents\Programming\Software Engineering\Code\DiscordManager\.venv\lib\site-packages\aiohttp\connector.py", line 874, in _resolve_host
    addrs = await self._resolver.resolve(host, port, family=self._family)
  File "C:\Users\Victor Momodu\Documents\Programming\Software Engineering\Code\DiscordManager\.venv\lib\site-packages\aiohttp\resolver.py", line 33, in resolve
    infos = await self._loop.getaddrinfo(
  File "C:\Users\Victor Momodu\AppData\Local\Programs\Python\Python310\lib\asyncio\base_events.py", line 860, in getaddrinfo
    return await self.run_in_executor(
  File "C:\Users\Victor Momodu\AppData\Local\Programs\Python\Python310\lib\concurrent\futures\thread.py", line 58, in run
    result = self.fn(*self.args, **self.kwargs)
  File "C:\Users\Victor Momodu\AppData\Local\Programs\Python\Python310\lib\socket.py", line 955, in getaddrinfo
    for res in _socket.getaddrinfo(host, port, family, type, proto, flags):
socket.gaierror: [Errno 11001] getaddrinfo failed

The above exception was the direct cause of the following exception:

Traceback (most recent call last):
  File "C:\Users\Victor Momodu\Documents\Programming\Software Engineering\Code\DiscordManager\.venv\lib\site-packages\discord\client.py", line 656, in connect
    self.ws = await asyncio.wait_for(coro, timeout=60.0)
  File "C:\Users\Victor Momodu\AppData\Local\Programs\Python\Python310\lib\asyncio\tasks.py", line 445, in wait_for
    return fut.result()
  File "C:\Users\Victor Momodu\Documents\Programming\Software Engineering\Code\DiscordManager\.venv\lib\site-packages\discord\gateway.py", line 372, in from_client
    socket = await client.http.ws_connect(str(url))
  File "C:\Users\Victor Momodu\Documents\Programming\Software Engineering\Code\DiscordManager\.venv\lib\site-packages\discord\http.py", line 537, in ws_connect
    return await self.__session.ws_connect(url, **kwargs)
  File "C:\Users\Victor Momodu\Documents\Programming\Software Engineering\Code\DiscordManager\.venv\lib\site-packages\aiohttp\client.py", line 779, in _ws_connect
    resp = await self.request(
  File "C:\Users\Victor Momodu\Documents\Programming\Software Engineering\Code\DiscordManager\.venv\lib\site-packages\aiohttp\client.py", line 536, in _request
    conn = await self._connector.connect(
  File "C:\Users\Victor Momodu\Documents\Programming\Software Engineering\Code\DiscordManager\.venv\lib\site-packages\aiohttp\connector.py", line 540, in connect
    proto = await self._create_connection(req, traces, timeout)
  File "C:\Users\Victor Momodu\Documents\Programming\Software Engineering\Code\DiscordManager\.venv\lib\site-packages\aiohttp\connector.py", line 901, in _create_connection
    _, proto = await self._create_direct_connection(req, traces, timeout)
  File "C:\Users\Victor Momodu\Documents\Programming\Software Engineering\Code\DiscordManager\.venv\lib\site-packages\aiohttp\connector.py", line 1166, in _create_direct_connection
    raise ClientConnectorError(req.connection_key, exc) from exc
aiohttp.client_exceptions.ClientConnectorError: Cannot connect to host gateway-us-east1-b.discord.gg:443 ssl:default [getaddrinfo failed]
[2023-07-11 07:35:22] [INFO    ] discord.gateway: Shard ID None has successfully RESUMED session b29fdab436fac0494ba42fc65400c1e9.
[2023-07-11 07:56:48] [INFO    ] discord: Logged in as ajoke#0521 (ID: 1123604895300329502).
[2023-07-11 07:57:32] [INFO    ] discord: Logged in as ajoke#0521 (ID: 1123604895300329502).
[2023-07-11 08:06:55] [INFO    ] discord: Logged in as ajoke#0521 (ID: 1123604895300329502).
